<?xml version= "1.0"?>
<robot name= "excample2">
   <link name= "base_link">
    <visual>
      <geometry>
       <box size= "0.39 0.29 0.08"/>
       </geometry>
        <material name="grey" >
       <color rgba="0.5 0.5 0.5 1" />
      </material>
    </visual>
 </link>


<link name= "down_box">
    <visual>
     <geometry>
      <box size= "0.18 0.29 0.08"/>
       </geometry>
          <material name="grey" >
          <color rgba="0.5 0.5 0.5 1" />
       </material>
     </visual>
  </link>


<joint name="base_to_down_box" type="fixed">
    <parent link="base_link"/>
    <child link="down_box"/>
   <origin xyz="0.105 0  -0.08" rpy="0 0 0"/>
  </joint>


<link name= "upper_surface">
    <visual>
     <geometry>
      <box size= "0.43 0.43 0.02"/>
      </geometry>
        <material name="grey" >
       <color rgba="0.5 0.5 0.5 1" />
        <origin xyz="0 0 0.04" rpy="0 0 1.57"/>
      </material>
    </visual>
 </link>

<joint name="base_to_upper_surface" type="fixed">
    <parent link="base_link"/>
    <child link="upper_surface"/>
   <origin xyz="0 0 0.04" rpy="0 0 0"/>
  </joint>



 <link name= "front_surface">
    <visual>
     <geometry>
      <box size= "0.02 0.29 0.16"/>
      </geometry>
        <material name="grey" >
       <color rgba="0.5 0.5 0.5 1" />
      </material>
    </visual>
 </link>



<joint name="base_to_front_surface" type="fixed">
    <parent link="base_link"/>
    <child link="front_surface"/>
   <origin xyz="0.205 0  -0.04" rpy="0 0 0"/>
I  </joint>



<link name= "back_surface">
    <visual>
     <geometry>
      <box size= "0.02 0.43 0.08"/>
       </geometry>
        <material name="grey" >
       <color rgba="0.5 0.5 0.5 1" />
      </material>
    </visual>
 </link>

<joint name="base_to_back_surface" type="fixed">
    <parent link="base_link"/>
    <child link="back_surface"/>
   <origin xyz="-0.205 0 0.01" rpy="0 0 0"/>
  </joint>



<link name= "left_front_wheel">
    <visual>
     <origin xyz="0 0 0" rpy="1.57 0 0" />
     <geometry>
      <cylinder length="0.0450" radius="0.09"/>
       </geometry>
         <material name="blackish">
         <color rgba="0.2 0.2 0.2 1"/>
      </material>
    </visual>
 </link>


 <joint name="left_front_wheel_joint" type="continuous">
    <axis xyz="0 0 1"/>
    <parent link="down_box"/>
    <child link="left_front_wheel"/>
    <origin rpy="0 0 0" xyz="0.08 0.17 0"/>
    <limit effort="100" velocity="100"/>
    <joint_properties damping="0.0" friction="0.0"/>
  </joint>


<link name= "right_front_wheel">
    <visual>
     <origin xyz="0 0 0" rpy="-1.57 0 0" />
     <geometry>
      <cylinder length="0.0450" radius="0.09"/>
       </geometry>
         <material name="blackish">
         <color rgba="0.2 0.2 0.2 1"/>
      </material>
    </visual>
 </link>


 <joint name="right_front_wheel_joint" type="continuous">
    <axis xyz="0 0 1"/>
    <parent link="down_box"/>
    <child link="right_front_wheel"/>
    <origin rpy="3.14 3.14 0" xyz="0.08 -0.17 0"/>
    <limit effort="100" velocity="100"/>
    <joint_properties damping="0.0" friction="0.0"/>
  </joint>


<link name= "base_left_back_wheel">
    <visual>
     <geometry>
      <cylinder length="0.04" radius="0.035"/>
       </geometry>
         <material name="blackish">
         <color rgba="0.2 0.2 0.2 1"/>
      </material>
    </visual>
 </link>


 <joint name="base_to_base_left_back_wheel_joint" type="fixed">
    <axis xyz="0 0 0"/>
    <parent link="base_link"/>
    <child link="base_left_back_wheel"/>
    <origin rpy="0 0 0" xyz="0 0 0"/>
    <limit effort="100" velocity="100"/>
    <joint_properties damping="0.0" friction="0.0"/>
  </joint>



<link name= "left_back_wheel">
    <visual>
     <origin xyz="0 0 0" rpy="1.57 0 0" />
     <geometry>
      <sphere radius="0.035"/>
       </geometry>
         <material name="white">
      </material>
    </visual>
 </link>


 <joint name="left_back_wheel_joint" type="continuous">
    <axis xyz="0 0 0"/>
    <parent link="base_left_back_wheel"/>
    <child link="left_back_wheel"/>
    <origin rpy="0 0 0" xyz="0 0 0"/>
    <limit effort="100" velocity="100"/>
    <joint_properties damping="0.0" friction="0.0"/>
  </joint>


<link name= "base_right_back_wheel">
    <visual>
     <origin xyz="0 0 0" rpy="-1.57 0 0" />
     <geometry>
      <cylinder length="0.04" radius="0.035"/>
       </geometry>
         <material name="blackish">
         <color rgba="0.2 0.2 0.2 1"/>
      </material>
    </visual>
 </link>

 <joint name="base_to_base_right_back_wheel_joint" type="fixed">
    <axis xyz="0 0 0"/>
    <parent link="base_link"/>
    <child link="base_right_back_wheel"/>
    <origin rpy="0 0 0" xyz="0 0 0"/>
    <limit effort="100" velocity="100"/>
    <joint_properties damping="0.0" friction="0.0"/>
  </joint>



<link name= "right_back_wheel">
    <visual>
     <origin xyz="0 0 0" rpy="-1.57 0 0" />
     <geometry>
       <sphere radius="0.035"/>
       </geometry>
         <material name="white">
      </material>
    </visual>
 </link>


 <joint name="right_back_wheel_joint" type="continuous">
    <axis xyz="0 0 1"/>
    <parent link="base_right_back_wheel"/>
    <child link="right_back_wheel"/>
    <origin rpy="0 0 0" xyz="0 0 0"/>
    <limit effort="100" velocity="100"/>
    <joint_properties damping="0.0" friction="0.0"/>
  </joint>

</robot>
